Workbook

Sheet Anleitung
A1: ANLEITUNG ZUR NUTZUNG DER INNOVATIONSPIPELINE
A3: ÜBERSICHT
A4: Diese Excel-Datei dient zur systematischen Erfassung und Bewertung von App-Ideen
A5: basierend auf einer Analyse der TOP 50 Probleme mit Technologielösungsbedarf.
A7: TABELLENBLÄTTER:
A8: 1. Dashboard - Übersicht und KPIs
A9: 2. App-Ideen Liste - Erfassung neuer Ideen mit Scoring
A10: 3. Trendanalyse TOP 50 - Analysierte Probleme als Ideenquelle
A11: 4. Anleitung - Diese Hilfeseite
A13: SCORING-SYSTEM:
A15: Für jede Idee werden 4 Dimensionen bewertet (1-10):
A16: • Marktpotenzial: Wie groß ist der adressierbare Markt?
... A23: OPPORTUNITY SCORE FORMEL:
A24: =(Marktpotenzial + Dringlichkeit + Machbarkeit) * (10 - Wettbewerb) / 30 -> #NAME?
A26: → Maximaler Score: 10 (perfekte Opportunity)
A27: → Je höher der Score, desto attraktiver die Idee
A29: PRIORITÄT (automatisch berechnet):
A30: • Sehr Hoch: Opportunity Score >= 7
A31: • Hoch: Opportunity Score >= 5
A32: • Mittel: Opportunity Score >= 3
A33: • Niedrig: Opportunity Score < 3
A35: DEUTSCHLAND-RELEVANZ (Blatt 2):
A36: 4 = Sehr hoch (Deutschland-spezifisches Problem)
A37: 3 = Hoch (DACH-Region betroffen)
A38: 2 = Mittel (EU-weites Problem)
A39: 1 = Niedrig (Globales Problem, DE wenig betroffen)
... A51: METHODE: K6 ISTQB (Erschaffen)

Sheet Dashboard
A1: INNOVATIONSPIPELINE 2025 - DASHBOARD
A2: Version 2.0 | Erstellt: 2025-01-26 | Antigrafity Projekte
A4: KENNZAHLEN
A5: Anzahl App-Ideen: | B5: =COUNTA('App-Ideen Liste'!A:A)-1 -> 47
A6: Davon "Sehr Hoch" Priorität: | B6: =COUNTIF('App-Ideen Liste'!Q:Q,"Sehr Hoch") -> 2
A7: Davon "In Entwicklung": | B7: =COUNTIF('App-Ideen Liste'!V:V,"In Entwicklung") -> 0
A8: TOP 50 Probleme analysiert: | B8: =COUNTA('Trendanalyse TOP 50'!A:A)-1 -> 50
A9: Davon DE-Relevanz >= 3: | B9: =COUNTIF('Trendanalyse TOP 50'!F:F,">=3") -> 50
A10: Durchschn. Opportunity Score: | B10: =AVERAGE('Trendanalyse TOP 50'!P:P) -> 24
A12: TOP 5 OPPORTUNITIES (Nach Score)
A13: Rang | B13: Problem | C13: Branche | D13: Opp. Score
A14: 1 | B14: (Nach Score sortieren in Blatt 2)
A19: Hinweis: Blatt 'Trendanalyse TOP 50' nach Spalte P sortieren für aktuelle TOP 5
A21: WORKFLOW
A22: 1. Blatt 'Trendanalyse TOP 50' nach Opportunity Score (Spalte P) sortieren
A23: 2. Vielversprechende Probleme identifizieren (hoher Score, niedrige Wettbewerbsintensität)
A24: 3. Neue App-Idee in Blatt 'App-Ideen Liste' anlegen
A25: 4. In Spalte 'Basiert auf Problem #' die Referenz eintragen
A26: 5. Scoring durchführen und Priorität automatisch berechnen lassen
A27: 6. Status regelmäßig aktualisieren

Sheet _Listen
A1: Branchen | B1: Status | C1: DE-Relevanz
A2: Gesundheit | B2: Ideenphase | C2: 4
A3: Immobilien | B3: Konzeptphase | C3: 3
A4: KMU/Mittelstand | B4: Validierung | C4: 2
A5: IT/Sicherheit | B5: In Entwicklung | C5: 1
A6: Logistik | B6: MVP fertig
A7: Bildung | B7: Live
A8: Energie | B8: Pausiert
A9: Verwaltung | B9: Abgelehnt
A10: Bauwesen
A11: Finanzen
A12: HR/Personal
A13: Recht
A14: Landwirtschaft
A15: KI/Tech
A16: Mobilität
A17: Kommunikation
A18: E-Commerce
A19: Medien/Info
A20: Nachhaltigkeit
A21: Sonstige

Sheet App-Ideen Liste
A1: Universelle Lade-App mit Echtzeit-Verfügbarkeit fehlt | B1: App-Name | C1: Branche | D1: Verantwortlicher | E1: Welle | F1: Zielgruppe | G1: Problembeschreibung | H1: Lösungsansatz | I1: USP (Alleinstellungsmerkmal) | J1: Wettbewerber | K1: Marktpotenzial (1-10) | L1: Dringlichkeit (1-10) | M1: Machbarkeit (1-10) | N1: Wettbewerbsintensität (1-10) | O1: Gesamtscore | P1: Opportunity Score | Q1: Priorität | R1: Basiert auf Problem # | S1: Entwicklungsaufwand | T1: Technologie-Stack | U1: Regulatorische Anforderungen | V1: Monetarisierung | W1: Status | X1: Verantwortlich | Y1: Erstellt am | Z1: Bemerkungen | AA1: Domain
A2: APP-001 | B2: Rent Navigator | C2: Immobilien | D2: Waleri | E2: 3 | F2: Vermieter, Hausverwaltungen | G2: Manuelle Verwaltung von Mieteinnahmen, Kundenbeziehungen und Verträgen ist zeitaufwändig und fehleranfällig | H2: App für Verwaltung von Mieteinnahmen, CRM für Mieter/Lieferanten, automatische Vertragserstellung | I2: Automatische Generierung gesetzeskonformer Mietverträge und Übergabeprotokolle gemäß BGB | J2: Haufe, Vermietet.de, Immoware24 | K2: 8 | L2: 7 | M2: 8 | N2: 6 | O2: =AVERAGE(K2:N2) -> 7.25 | P2: =(K2+L2+M2)*(10-N2)/30 -> 3.0666667 | Q2: =IF(P2>=7,"Sehr Hoch",IF(P2>=5,"Hoch",IF(P2>=3,"Mittel","Niedrig"))) -> Mittel | R2: 6 | S2: 6-9 Monate | T2: React, Node.js, PostgreSQL | U2: DSGVO, Mietrecht BGB | V2: SaaS Abo-Modell | W2: In Entwicklung | X2: Team Alpha | Y2: 2025-01-26 | Z2: MVP bereits gestartet | AA2: rent-navigator.ai, Immobilien-navigator.ai
A3: APP-002 | B3: HealthBridge | C3: Gesundheit | F3: Patienten, Ärzte, Pflegedienste | G3: Mangelnde Kommunikation zwischen Patienten, Ärzten und Pflegediensten führt zu Behandlungsfehlern | H3: Integrierte Plattform für Patientendaten, Termine, Medikation mit Echtzeit-Kommunikation | I3: KI-gestützte Medikamenteninteraktionsprüfung und automatische Erinnerungen | J3: Doctolib, Jameda, CGM | K3: 9 | L3: 9 | M3: 6 | N3: 7 | O3: =AVERAGE(K3:N3) -> 7.75 | P3: =(K3+L3+M3)*(10-N3)/30 -> 2.4 | Q3: =IF(P3>=7,"Sehr Hoch",IF(P3>=5,"Hoch",IF(P3>=3,"Mittel","Niedrig"))) -> Niedrig | R3: 1 | S3: 12-18 Monate | T3: Flutter, Python, FHIR | U3: MDR, DSGVO, DiGA-Verordnung | V3: B2B Lizenzmodell + Krankenkassen | W3: Ideenphase | X3: - | Y3: 2025-01-26 | Z3: Regulatorische Hürden prüfen | AA3: meine-gesundheit.ai
A4: APP-003 | B4: MittelstandDigital | C4: KMU/Mittelstand | D4: Nikolaj | E4: 5 | F4: Deutsche KMU 10-250 MA | G4: 53% der KMU haben Probleme mit Digitalisierung, fehlende integrierte Lösungen für E-Rechnung, Buchhaltung, CRM | H4: All-in-One Plattform für KMU: E-Rechnung (ab 2025 Pflicht), Buchhaltung, CRM, Projektmanagement | I4: Speziell für deutsche Compliance (GoBD, E-Rechnung XRechnung), einfache Bedienung | J4: Lexoffice, sevDesk, Sage | K4: 8 | L4: 9 | M4: 7 | N4: 8 | O4: =AVERAGE(K4:N4) -> 8 | P4: =(K4+L4+M4)*(10-N4)/30 -> 1.6 | Q4: =IF(P4>=7,"Sehr Hoch",IF(P4>=5,"Hoch",IF(P4>=3,"Mittel","Niedrig"))) -> Niedrig | R4: 9 | S4: 9-12 Monate | T4: Vue.js, .NET, SQL Server | U4: GoBD, DSGVO, E-Rechnungsgesetz | V4: Freemium + Premium Abo | W4: Konzeptphase | X4: - | Y4: 2025-01-26 | Z4: E-Rechnung 2025 als Treiber | AA4: mittelstanddigital.ai
A5: APP-004 | B5: Skillmapping (Kompetenzkompass) | C5: Alle | D5: Daniel | E5: 3 | F5: Personalabteilung | G5: Unternehmen kennen die tatsächlichen Fähigkeiten ihrer Mitarbeiter nicht. Manuelle Kompetenzmatrizen veralten sofort, was zu teurem externen Recruiting führt, obwohl intern "versteckte" Talente für neue Projekte vorhanden wären ("Skill-Gap"). | H5: Ein KI-gestützter Prozessablauf, der Fähigkeiten automatisch aus Texten (Lebensläufe, Projekt-Logs, Zertifikate) extrahiert und eine dynamische Skill-Datenbank erstellt. Bei neuen Anforderungen (Jobs/Projekte) matcht die KI automatisch die besten internen Kandidaten. | I5: "Zero-Manual-Entry" – Die KI inferiert und aktualisiert Skills automatisch im Hintergrund. Fokus auf KMU durch extrem simple Integration ohne riesiges Enterprise-Software-Projekt. | J5: Eightfold AI, TechWolf, MuchSkills, Workday Skills Cloud (oft zu teuer/komplex für KMU), klassische Excel-Listen. | K5: 8 | L5: 8 | M5: 7 | N5: 7 | O5: 7.5 | P5: 3 | Q5: Mittel-Hoch | R5: 12 | S5: 6-9 Monate | T5: Python (Backend), React (Frontend), Graphdatenbank (z.B. Neo4j für das Skill-Netzwerk), Open-Source LLMs (für Datenschutz) oder OpenAI API. | U5: DSGVO (extrem sensibel bei Mitarbeiterdaten!), zwingende Zustimmung des Betriebsrats (darf nicht zur reinen Leistungskontrolle missbraucht werden). | V5: B2B SaaS-Abo (Preis pro Mitarbeiter/Monat, z.B. 2-5 € pro Kopf) | W5: Ideenphase | X5: Team HR-Tech / Innovation | Y5: 46075 | Z5: Kritischer Erfolgsfaktor im DACH-Raum ist der Betriebsrat. Die App muss zwingend als "Karriere- und Weiterbildungs-Tool" für den Mitarbeiter positioniert werden (Empfehlungen für Trainings), nicht als Überwachungstool. Ein Open-Source LLM (lokal gehostet) ist für HR-Daten stark zu empfehlen. | AA5: kompetenzkompass.app
A6: APP-005 | B6: AI SafeGuard Proxy | C6: IT-Security / Branchenübergreifende B2B-Software | D6: Yash | E6: 3 | F6: Mittelständische Unternehmen (KMU), Großkonzerne, CISOs (Chief Information Security Officers), IT-Administratoren | G6: Ungesteuerte Nutzung von KI im Unternehmen führt zu extremen Risiken: Datenabfluss (DSGVO-Verstöße), Ausführung toxischer Prompts (Prompt Injections) und Fehlentscheidungen durch KI-Halluzinationen. | H6: Eine Middleware/Gateway-App, die als Proxy zwischen Mitarbeitern und externen KI-Modellen agiert. Sie filtert sensible Daten aus Prompts (DLP), blockiert böswillige Anfragen und prüft die KI-Antworten auf Richtigkeit und Compliance. | I6: Echtzeit-Anonymisierung von PII (personenbezogenen Daten) vor dem Senden an die KI, vollständige Audit-Logs für Compliance-Prüfungen und flexibler Wechsel zwischen KIs (OpenAI, Anthropic, Gemini) im Hintergrund. | J6: Cloudflare AI Gateway, Nvidia NeMo Guardrails (als Framework), Lakera, Portkey | K6: 9 | L6: 9 | M6: 7 | N6: 6 | O6: 7.75 | P6: 2.5 | Q6: Hoch | R6: 5 | S6: 6-9 Monate | T6: Python, FastAPI, PostgreSQL (für Audit-Logs), Redis (für Caching & Rate Limiting), Docker/Kubernetes (für sicheres On-Premise-Hosting) | U6: DSGVO, EU AI Act, ISO 27001 (Informationssicherheit) | V6: B2B SaaS-Modell (Abrechnung pro Nutzer/Monat) oder Enterprise-Jahreslizenz für lokales Hosting (On-Premise) | W6: Konzeptphase | X6: - | Y6: 46075 | Z6: Nicht den kompletten Filter selbst bauen! Stattdessen Fokus auf eine gute Benutzeroberfläche für Administratoren und die Integration bewährter Open-Source-Sicherheitsfilter (wie Llama-Guard oder NeMo Guardrails) in das Backend. | AA6: ai-gaurd.ai, ki-schutz.ai
A7: APP-006 | B7: Finance-Safe | C7: Finanzen | F7: Alle Personen, die ihre Finanzen mehr kontrolieren wollen | G7: Viele Menschen haben Probleme mit ihren Finanzen und es fällt ihnen schwer zu sparen. Ständig ist das Geld knapp und auch wenn das Gehalt steigt, reicht es nach kurzer Zeit nicht aus und man kann nichts zur Seite legen | H7: Eine App, die Sparplan beinhaltet und den Nutzer dazu bringt mehr Kontrolle über seine Finanzen zu bekommen und gelichzeitig den Nutzer zum sparen bringt | J7: Viele unterschiedliche Anbieter. Einer der größten ist FinanzGuru | K7: 6 | L7: 6 | M7: 8 | N7: 7 | O7: =AVERAGE(K7:N7) -> 6.75 | Q7: Mittel | S7: 1 Monat | W7: Ideenphase | Y7: 46077 | AA7: finance-Safe.ai, finance-helper.ai, finance-tracker.ai, finance-minister.ai,
A8: APP-007 | B8: MycoTrace | C8: Agrar-Tech | F8: Regenerative Landwirte, Großbetriebe | G8: Bodenverschlechterung ist unsichtbar. Mykorrhiza-Netzwerke (Pilze) im Boden, die für Ertrag und CO2-Speicherung essenziell sind, können bisher nicht live überwacht werden. | H8: App gekoppelt mit günstigen, biologisch abbaubaren Bodensensoren, die die chemische Kommunikation des Pilznetzwerks in Echtzeit als "Underground Map" visualisieren. | I8: Weltweit erstes Tool zur Live-Kartierung unterirdischer Biodiversität zur massiven Einsparung von Kunstdünger. | J8: Laboranalysen (teuer, langsam), klassische Bodenfeuchtesensoren (CropX) | K8: 9 | L8: 8 | M8: 4 | N8: 2 | O8: 5.75 | P8: 4.2 | Q8: Hoch | R8: 45 | S8: 18-24 Monate | T8: Python (AI-Auswertung), React Native, IoT-Protokolle (LoRaWAN) | U8: EU-Agrarrichtlinien, Düngeverordnung | V8: Hardware-Verkauf + SaaS-Abo für prädiktive Datenanalyse | W8: Ideenphase | X8: Team DeepTech | Y8: 46083 | Z8: Benötigt starke Partnerschaft mit Agrarforschungsinstituten für die Sensor-Hardware. | AA8: mycotrace.ai
A9: APP-008 | B9: NeuroFlow Workspace | C9: HR / Smart Building | F9: Großkonzerne, Neurodivergente Arbeitnehmer | G9: Großraumbüros führen bei neurodivergenten Menschen (z.B. ADHS, Autismus) oft zu Reizüberflutung. Starre Umgebungen mindern die Inklusion und Produktivität. | H9: App, die sich mit Wearables (Puls, HRV) und Smart-Office-Systemen verbindet, um Licht, Geräuschunterdrückung und Raumtemperatur am Platz an den kognitiven Zustand anzupassen. | I9: Biometrisch gesteuerte, hyperpersonalisierte Raumumgebung für echte kognitive Barrierefreiheit im Büro. | J9: Keine direkten; Smart-Lighting-Anbieter (Philips Hue) aber ohne biometrischen/HR-Fokus | K9: 8 | L9: 7 | M9: 6 | N9: 3 | O9: 6 | P9: 3.1 | Q9: Mittel | R9: 52 | S9: 12-18 Monate | T9: Swift, Kotlin, BLE (Bluetooth Low Energy), Matter-Protokoll | U9: DSGVO (Gesundheitsdaten extrem sensibel!) | V9: B2B Enterprise-Lizenzen (finanziert aus dem Inklusions- & ESG-Budget) | W9: Ideenphase | X9: Team Alpha | Y9: 46083 | Z9: Sehr starke Positionierung als ESG/Inklusions-Maßnahme. Echter Impact für Betroffene. | AA9: https://www.google.com/search?q=neuroflow-workspace.com
A10: APP-009 | B10: DataDividend | C10: Web3 / KI-Ethik | F10: Heavy-Internet-User, Content Creator | G10: Nutzer generieren permanent wertvolle Trainingsdaten für KI-Modelle, werden dafür aber weder um Erlaubnis gefragt noch kompensiert. | H10: Eine "Personal Data Wallet" (Browser-Extension/Mobile App), die Nutzerdaten lokal verschlüsselt und es erlaubt, Datenströme anonymisiert direkt an KI-Entwickler gegen Mikrozahlungen zu leasen. | I10: Umkehrung des Datenmarktes: Nutzer werden zu aktiven, bezahlten Daten-Providern mit absoluter lokaler Kontrolle (Zero-Knowledge-Proofs). | J10: Brave Browser (BAT-Token), diverse gescheiterte Web3-Datenmarktplätze | K10: 10 | L10: 9 | M10: 5 | N10: 5 | O10: 7.25 | P10: 3.8 | Q10: Hoch | R10: 18 | S10: 12-18 Monate | T10: Rust (Core), React, Zero-Knowledge-Proofs (zk-SNARKs), Stripe / Krypto (Micropayments) | U10: DSGVO, AI Act, Finanzmarktrichtlinien (je nach Auszahlung) | V10: Transaktionsgebühr bei Daten-Leasing (z.B. 15% Cut) | W10: Ideenphase | X10: Team Innovation | Y10: 46083 | Z10: Technisch hochkomplex, trifft aber genau den eskalierenden Zeitgeist bzgl. KI-Urheberrecht. | AA10: datadividend.io
A11: APP-010 | B11: ARchitect X-Ray | C11: Handwerk / PropTech | F11: Installateure, Baufirmen, DIY-Heimwerker | G11: Beim Bohren in Wände werden oft Leitungen getroffen, da Bestandspläne veraltet sind und gängige Ortungsgeräte unpräzise und fehleranfällig arbeiten. | H11: AR-App, die das Smartphone-LiDAR mit digitalen Bauplänen und aufsteckbaren Wärmebildkameras (FLIR) kombiniert, um ein 3D-Hologramm der Leitungen auf die Wand zu projizieren. | I11: Erste Consumer/Prosumer-ready "Röntgenblick"-AR, die thermische und strukturelle Daten in Echtzeit auf dem Screen fusioniert. | J11: Bosch Ortungsgeräte, Walabot DIY | K11: 9 | L11: 8 | M11: 6 | N11: 4 | O11: 6.75 | P11: 3.4 | Q11: Mittel-Hoch | R11: 33 | S11: 12-15 Monate | T11: Unity, ARKit (iOS) / ARCore (Android), Computer Vision Modelle | U11: Produkthaftungsgesetz | V11: Freemium (Basis-Scan) + Hardware-Vermittlung + Pro-Abo für Handwerker | W11: Ideenphase | X11: - | Y11: 46083 | Z11: Smartphone-Hardware ist mittlerweile stark genug dafür (LiDAR ist bei Apple Pro-Modellen Standard). | AA11: https://www.google.com/search?q=architect-xray.com
A12: APP-011 | B12: UrbanMiner | C12: Bauwesen / Circular Economy | F12: Architekten, Bauunternehmen, Stadtplaner | G12: Beim Gebäudeabriss werden wertvolle Rohstoffe vernichtet (Downcycling), da niemand weiß, was exakt verbaut wurde. Ein massives Problem für die Kreislaufwirtschaft. | H12: App zur digitalen Erfassung jedes Bauteils während der Bau- oder Sanierungsphase. Erstellt einen "digitalen Zwilling" als Materialpass für spätere Wiederverwendung (Urban Mining). | I12: Schließt die chronische Datenlücke zwischen Gebäudeerrichtung und Rückbau nach 50 Jahren mittels dezentraler Datenbanken. | J12: Madaster (eher Plattform, keine On-Site App), Concular | K12: 8 | L12: 9 | M12: 7 | N12: 4 | O12: 7 | P12: 3.5 | Q12: Hoch | R12: 61 | S12: 9-12 Monate | T12: React Native, GraphQL, Graph-Datenbanken (Neo4j), IPFS / Blockchain für Unveränderlichkeit | U12: Bauordnungen, neue EU-Gebäuderichtlinien (EPBD) | V12: B2B SaaS (Preis pro erfasstem Bauprojekt/Quadratmeter) | W12: Ideenphase | X12: Team Beta | Y12: 46083 | Z12: Gesetzlicher Druck für zirkuläres Bauen nimmt in der EU aktuell massiv zu. Timing ist ideal. | AA12: urbanminer-app.de
A13: APP-012 | B13: DailyEcho | C13: Personal Growth / Mental Wellness | D13: Erwin | E13: 3 | F13: Berufstätige, Studierende, Menschen mit Fokus auf mentale Gesundheit | G13: Klassisches Journaling scheitert oft an mangelnder Konsistenz und Überforderung ("Was soll ich schreiben?"). Zudem fehlt nach dem Aufschreiben negativer Erlebnisse oft ein Lösungsansatz. | H13: Eine App, die täglich kontextbezogene Reflexionsfragen stellt (Learnings, Highs, Lows) und basierend auf der Sentiment-Analyse (Stimmungsbild) der Antworten maßgeschneiderte Mikro-Aktivitäten oder Content vorschlägt. | I13: Die Kombination aus dynamischem Abfragen und sofortiger, KI-generierter "Erste Hilfe" (z.B. eine spezifische Atemübung bei Stress, ein passender Podcast bei Motivationsverlust). | J13: Reflectly, stoic., Day One, Journey | K13: 9 | L13: 7 | M13: 8 | N13: 8 | O13: 8 | P13: 2.8 | Q13: Mittel-Hoch | R13: 74 | S13: 4-6 Monate | T13: Flutter (Frontend für iOS/Android), Python/FastAPI (Backend), LLM API (für Stimmungsanalyse & Content-Matching) | U13: DSGVO (extrem sensibel, da psychologisches Profiling!), AI Act | V13: Freemium (Basis-Reflexion kostenlos, personalisierte Content-Vorschläge & Deep-Dives im Premium-Abo) | W13: Ideenphase | X13: Team Alpha | Y13: 46083 | Z13: Lokale Datenverschlüsselung (On-Device) ist hier ein absolutes Muss, um das Vertrauen der Nutzer zu gewinnen. | AA13: dailyecho-app.de
A14: APP-013 | B14: WedBudget | C14: Sonstige | D14: Daniel | E14: 4 | F14: Verlobte Paare (Selbstplaner), die Wert auf Budgetkontrolle und Struktur legen | G14: Unvorhergesehene Kosten, unübersichtliche Excel-Listen und verstreute Anbieterkontakte führen zu Stress und Budgetüberschreitungen. | H14: Eine zentrale App, die dynamische Budgetkalkulation (basierend auf Region/Gästen) mit CRM-Funktionen für Dienstleister kombiniert. | I14: „Smart Budgeting“: Automatische Kostenschätzung basierend auf regionalen Preis-Indizes und Echtzeit-Anpassung bei Dienstleister-Zuweisung. | J14: https://www.google.com/search?q=WeddingPlanner.com, The Knot, klassische Excel-Templates, spezialisierte Hochzeitsagenturen | K14: 8 | L14: 6 | M14: 9 | N14: 7 | O14: 30 | P14: Hoch | Q14: Hoch | S14: 2 Wochen | T14: Frontend: React Native oder Flutter (für iOS/Android Cross-Platform). Backend: Node.js mit PostgreSQL (für komplexe Datenbeziehungen). Dashboard: Chart.js oder D3.js für die visuelle Kostenverteilung. | U14: DSGVO-Konformität (besonders sensibel bei Kontakt- und Budgetdaten). | V14: Freemium-Modell (Basis-Budgetplaner kostenlos; Premium-Features wie Export, Team-Kollaboration oder Anbieter-Verzeichnis gegen Einmalzahlung). | W14: In Konzeption / Ideenphase. | X14: - | Y14: 46087 | Z14: Der Erfolg steht und fällt mit der Genauigkeit der regionalen Kostendaten (Benchmarks). | AA14: Anfrage ausstehend.
A15: APP-014 | B15: FreerideParadise | C15: Sonstige | F15: Alle Wintersportler, die in einer APP die beste Schneelage analysieren wollen | G15: Wenn man aus der Stadt in die Berge fährt, ist es oft ein Problem die Region zu finden, wo momentan die beste Schneelage ist | H15: In einer APP kann man sich die bekannstesten Skigebiete (zuerst DACH-Region) aussuchen und sofort die aktuelle Wetterlage zu abfragen in einer APP, zusätzlich kann man in die Webcams der Skigebiete abspringen | J15: wePowder (Prognosen), White Risk / SnowSafe (Lawinengefahr) und SNOWHOW (Routenplanung) | Y15: 46087
A16: APP-015 | B16: Backup-Pilot | D16: Erwin | E16: 1+2
A17: APP-016 | B17: Marketing Planer | C17: Medien/Info | D17: Daniel | F17: Manager, Agenturen, Inhouse-Teams | G17: Kampagnen laufen verteilt über viele Tools ohne End-to-End-Transparenz. | H17: Zentrale Kampagnenverwaltung mit 3-Schritt-Erstellung, Performance-Tab und Creative-Workflow. | I17: Kampagnenplanung + operative Ausführung + kanalbezogene KPIs in einer Oberfläche. | J17: HubSpot Marketing Hub, Asana, monday.com, ClickUp | K17: 10 | L17: 10 | M17: 8 | N17: 9 | O17: =AVERAGE(K17:N17) -> 9.25 | Q17: P1 | T17: Next.js, React, Supabase, Recharts | U17: DSGVO, Auftragsverarbeitung, Datenminimierung | V17: SaaS Pro-Plan pro Workspace + Nutzerstaffel | W17: Implementiert | X17: Product + Marketing Lead | Y17: 46101 | Z17: Core-Werttreiber der App. | AA17: momentum-marketing.app
A18: APP-017 | B18: IT Architekturplanner - plan-IT | D18: Niko | E18: 1
A19: APP-020 | B19: Verfügbarkeitsplanner - TeamRadar | D19: Niko | E19: 2
A20: APP-021 | B20: Monitoring - AppMonitor | D20: Niko | E20: 2
A21: APP-022 | B21: Zeiterfassung - TRACE | C21: V2 | D21: Niko | E21: 3 + 4
A22: APP-023 | B22: Urlaubsplaner - AWAY | C22: V2 | D22: Niko | E22: 3 + 4
A23: APP-024 | B23: Reality Check | D23: Nurzhan | E23: 3
A24: APP-027 | B24: Meine Wohnung(UrbanMiner, Architect X-Ray) | C24: V2 | D24: Yash | E24: 3 + 4
A25: APP-029 | B25: ='Trendanalyse TOP 50'!D9 -> Energiekosten KMU | D25: Erwin | E25: 4
A26: APP-030 | B26: Ladesäulen-Chaos | C26: Mobilität | D26: Nikolaj Schefner | E26: 6 | F26: Alle Autofahrer mit E-Mobilität | G26: Unterschiedliche Apps, Tarife für E-Auto-Laden | H26: Universelle Lade-App mit Echtzeit-Verfügbarkeit fehlt | I26: All-in-one-Lösung | J26: Viele Einzelapps | K26: 7 | L26: 8 | M26: 7 | N26: 7 | O26: =AVERAGE(K26:N26) -> 7.25 | P26: =(K26+L26+M26)*(10-N26)/30 -> 2.2
A27: APP-031 | B27: SmartCarMan | C27: Verwaltung | D27: Daniel | E27: 5 | F27: Private Fahrzeughalter (DACH), inkl. Mehrfahrzeug-Haushalte | G27: Kosten, Wartungen, Belege und Fristen sind verstreut und führen zu Intransparenz, vergessenen Terminen und schwacher Nachweislage beim Verkauf | H27: Zentrales digitales Fahrzeugkonto mit Fahrzeugprofilen, Kosten-/Tanktracking, Service-Erinnerungen, Dashboard, Beleg-/Kommentar-Doku, CSV-Export (Pro) | I27: Kombination aus Kostenkontrolle + Wartungslogik + Nachweisdokumentation in einem einfachen Freemium-Flow | J27: Fuelio, Spritmonitor, Drivvo, Werkstatt-/OEM-Apps, Excel/Notion-Eigenlösungen | K27: 9 | L27: 8 | M27: 8 | N27: 7 | O27: 32/40 | P27: 8.0/10 | Q27: Hoch | R27: P1 (fehlende Transparenz/Struktur in privater Fahrzeugverwaltung) | S27: Mittel (V1 bereits umgesetzt, Ausbau stufenweise) | T27: Next.js 16, TypeScript, Tailwind CSS v4, Supabase (Postgres/Auth/Storage/RLS), Vercel | U27: DSGVO, sichere Authentifizierung, rollenbasierter Datenzugriff (RLS), Impressum/Datenschutz/AGB | V27: Freemium: Free (1 Fahrzeug), Pro (unbegrenzt + CSV + erweiterte Features), geplantes Upgrade-/Abo-Modell | W27: In Umsetzung / V1 produktionsnah | X27: Daniel Moretz | Y27: Welle 5 | Z27: KI-Features (OCR, Prognosen, Smart Reminder) als geplanter Ausbau nach stabiler Datengrundlage
A28: APP-032 | B28: Vertragsmanager | C28: Verwaltung | D28: Daniel | E28: 6 | F28: KMU im DACH-Raum (GF, Office, IT-Admin), sekundär Kanzleien/Steuerberater | G28: Verträge/Abos sind verteilt, Fristen werden verpasst, unnötige Kosten und geringe Transparenz | H28: Zentrale Vertragsplattform mit Fristenmanagement, Analytics, Vorlagen, Multi-Tenant und Rollen | I28: DACH- und DSGVO-fokussiert, integrierte Fristlogik + Kostenanalyse + rechtliche Vorlagen in einer Lösung | J28: DocuSign CLM, Ironclad, PandaDoc, Vertragsheld, Excel/SharePoint | K28: 9 | L28: 9 | M28: 8 | N28: 7 | O28: 8.3 | P28: 8.2 | Q28: Hoch | R28: P-01 Fragmentiertes Vertragsmanagement | S28: Mittel bis hoch | T28: Next.js 16, TypeScript, Tailwind v4, Supabase, next-intl, Recharts | U28: DSGVO, AVV/DPA, LkSG/CSRD-relevante Dokumentation | V28: Freemium + Starter/Pro/Business Abo (später Stripe) | W28: MVP weitgehend umgesetzt; offen: OCR, E-Mail-Reminders, PDF/DOCX-Export, Billing | X28: Daniel Moretz | Y28: Welle 6 | Z28: Gute technische Basis und hoher Fit; größte Hebel sind OCR-Integration und Zahlungsanbindung | AA28: verwa.eu
A29: APP-033 | B29: BedarfsPilot | C29: Verwaltung | D29: Daniel | E29: 7 | F29: Handwerks-, Service- und Pflegebetriebe mit 5-250 Mitarbeitenden | G29: Bedarfe gehen in WhatsApp, Excel oder E-Mail verloren; Freigaben und Bestellungen sind unstrukturiert | H29: Mobile-first SaaS für Bedarfsmeldung, Freigabe, Bestellung, Katalog, Standorte und Reporting | I29: Sehr einfache mobile Bedarfserfassung direkt am Arbeitsplatz statt schwergewichtigem ERP-Workflow | J29: Excel, WhatsApp, Odoo, ERP-Module, einfache Einkaufstools | K29: 8 | L29: 8 | M29: 9 | N29: 7 | O29: 32/40 | P29: 8.0 | Q29: Hoch | R29: 1 | S29: Mittel | T29: Next.js 16, TypeScript, Tailwind v4, Supabase, next-intl | U29: DSGVO, Rollen-/Rechtekonzept, Mandantentrennung, rechtssichere Pflichtseiten | V29: SaaS-Abomodell pro Organisation/Plan | W29: V1 weitgehend umgesetzt | X29: Daniel Moretz | Y29: Welle 7 | Z29: Starke V1-Basis; Ausbaupotenzial bei KI-Empfehlungen, E-Mail und Uploads | AA29: bedarfspilot.de
A30: APP-034 | B30: Sirin | C30: KMU/Mittelstand | D30: Daniel | E30: 8 | F30: Dienstleistungsbetriebe mit Terminbuchung (Friseur, Barber, Kosmetik, Physio, Yoga) sowie Endkunden | G30: Fragmentierte Terminverwaltung, geringe Online-Sichtbarkeit, hoher manueller Buchungs-/Kommunikationsaufwand | H30: Multi-Tenant SaaS mit öffentlicher Buchungsseite, Dashboard, Suche/Karte, Favoriten, Benachrichtigungen | I30: Vertikale Lösung für lokale Serviceanbieter: Buchung + Discovery + öffentliches Profil + Multi-Tenant in einer Plattform | J30: Treatwell, Fresha, Shore, Planity, regionale Anbieter | K30: 8 | L30: 8 | M30: 9 | N30: 8 | O30: 45870 | P30: 7.2 | Q30: Hoch | R30: P-01 | S30: Mittel-Hoch | T30: Next.js 16, TypeScript, Tailwind v4, Supabase, next-intl, Leaflet/OpenStreetMap | U30: DSGVO, Impressumspflicht, Datenschutz/AGB, Cookie-/Tracking-Compliance | V30: B2B SaaS-Abo pro Organisation + Add-ons | W30: In Umsetzung (V1 produktionsnah) | X30: Daniel Moretz | Y30: Welle 8 | Z30: Kernmodule live; offene Ausbaustufen: Stripe, Reminder-Worker, Kalender-Sync
A31: APP-035 | B31: TreffPunkt | C31: Verwaltung | D31: Daniel | E31: 9 | F31: Privatpersonen für Gruppenevents 5–50 Teilnehmer (Klassentreffen, Freunde, Familie) | G31: WhatsApp-Organisation ist unstrukturiert: Termin-/Aufgaben-/Budget-Chaos, Infos gehen unter | H31: Mini-Event-Manager mit Terminvoting, Aufgaben, Budget/Kostenaufteilung, zentraler Eventseite, Remindern | I31: Kombination aus Termin, Aufgaben, Budget, Rollen, Übersicht und EU-Hosting in einem privaten Tool | J31: WhatsApp, Doodle, Splid, Eventbrite, Google Forms, SignUpGenius, Notion/Trello | K31: 9 | L31: 8 | M31: 8 | N31: 6 | O31: 18445 | P31: 75 | Q31: Hoch | R31: nicht angegeben | S31: Mittel (MVP 5 Werktage) | T31: Next.js, TypeScript, Tailwind, shadcn/ui, Supabase, Resend, Maps API, Calendar API, Stripe | U31: DSGVO bei Kontaktdaten; PSD2 wird umgangen, da nur Kostenaufteilung ohne Zahlungsdienst | V31: Freemium + Premium + Affiliate/Partner | W31: Zur Freigabe eingereicht | X31: Daniel Moretz | Y31: Offen, Welle 9 | Z31: Sehr hoher Nutzwert bei wiederkehrendem Alltagsproblem
A32: APP-036 | B32: BelegBox | C32: Verwaltung | D32: Daniel | E32: 9 | F32: Verbraucher und Selbstständige im DACH-Raum (Belegarchiv, Garantie, Steuer) | G32: Kassenzettel verblassen, Belege sind verteilt/nicht auffindbar, Steuer- und Garantie-Nachweise fehlen | H32: Browserbasierte Beleg-App mit Foto-Erfassung, lokaler Ablage, Suche/Filter, Garantie-Tracker, Export | I32: Privacy-first: V1 lokal im Browser ohne Cloud-Zwang + dedizierter Beleg-Workflow | J32: Expensify, 1Tap Receipts, Klarna Receipts, lexoffice/sevDesk, Google/Apple Fotos | K32: 8 | L32: 8 | M32: 9 | N32: 7 | O32: 45839 | P32: 73 | Q32: Hoch | R32: nicht angegeben | S32: Niedrig (MVP in 5 Werktagen) | T32: Next.js/SvelteKit, TypeScript, Tailwind, IndexedDB, idb, pdf-lib, JSZip, Stripe | U32: DSGVO-relevant; steuerliche Aufbewahrungskontexte; in V1 geringe Compliance-Last durch lokale Speicherung | V32: Freemium, später Pro (OCR, Cloud-Sync, DATEV) | W32: Zur Freigabe eingereicht | X32: Daniel Moretz | Y32: Offen, Welle 9 | Z32: Sehr guter DACH-Fit über Datenschutz und Alltagsnutzen | AA32: belegnest.de
A33: APP-037 | B33: KinderPartyPlaner | C33: Verwaltung | D33: Daniel | E33: 9 | F33: Eltern mit Kindern 3–12 Jahre (primär DACH), sekundär Großeltern/Kita | G33: Planungsstress, Informationschaos (Pinterest/Blogs), fehlende Mengen- und Ablaufplanung | H33: 5-Minuten-Wizard erzeugt kompletten Partyplan (Ablauf, Spiele, Einkauf, Einladung, PDF/WhatsApp) | I33: End-to-end Kindergeburtstags-Workflow ohne Account statt fragmentierter Einzeltools | J33: Pinterest, Mama-Blogs, Canva, Kindergeburtstag-Planen.de, ChatGPT | K33: 7 | L33: 6 | M33: 9 | N33: 5 | O33: 7.00 | P33: 70 | Q33: Hoch | R33: nicht angegeben | S33: Niedrig (2–3 Wochen; MVP 5 Werktage) | T33: Next.js/Astro, TypeScript, Tailwind, pdf-lib, html2canvas/dom-to-image, Stripe | U33: Gering; in V1 keine Kinderdaten nötig, minimale DSGVO-Anforderungen | V33: Einmalkauf/Pro-Pakete, Affiliate-Potenzial | W33: Zur Freigabe eingereicht | X33: Daniel Moretz | Y33: Offen, Welle 9 | Z33: Starkes virales Potenzial über geteilte Einladungen | AA33: geburtstagspilot.de
A34: APP-038 | B34: MeineZielcollage | C34: Sonstige | D34: Daniel | E34: 9 | F34: Digital-affine Erwachsene 25–45, plus Coaches/Studierende (sekundär) | G34: Vision Boards sind statisch, kein Tracking/Meilenstein-System, Motivation bricht ab | H34: Interaktive Zielkarten + Tracking + Gamification + KI-Vorschläge/Erinnerungen | I34: Kombination aus visuellem Vision Board, Zielsystem, Gamification und KI in einem Produkt | J34: Perfectly Happy, Vision Board App, Habitica, Streaks, Fabulous, Notion, Pinterest, Canva, Goalify | K34: 7 | L34: 5 | M34: 7 | N34: 8 | O34: 18384 | P34: 55 | Q34: Mittel | R34: nicht angegeben | S34: Mittel (MVP 5 Werktage, höheres UX-Polishing) | T34: Next.js (App Router), TypeScript, Tailwind, shadcn/ui, Supabase, OpenAI/Mistral, Stripe, Resend | U34: DSGVO (persönliche Zieldaten), EU-Hosting; EU AI Act-Hinweise für KI-Inhalte | V34: Freemium + Abo + In-App-Käufe + später B2B-Coach-Features | W34: Zur Freigabe eingereicht | X34: Daniel Moretz | Y34: Offen, Welle 9 | Z34: Höheres Differenzierungspotenzial, aber härterer Markt
A35: APP-039 | B35: Meine Wohnung | C35: PropTech | D35: Yash Bhesaniya | E35: 3 & 4 | F35: Vermieter, Hausverwaltungen, Architekten, Handwerker | G35: Gebäude- und Wohnungsdaten fragmentiert, Zusammenarbeit ineffizient | H35: Digitale 3D-Objektsicht mit Rollenrechten, Ressourcen-Tracking und X-Ray-Ansichten | I35: Kombination aus kollaborativer 3D-Ansicht und operativem Gebäudemanagement | J35: PlanRadar, Vermietet.de, iDWELL, Objego | K35: 8 | L35: 7 | M35: 7 | N35: 8 | O35: 7.5 | P35: 2.3 | Q35: Mittel | R35: 13 | S35: Mittel bis hoch | T35: Web-SaaS Plattform (3D-Editor, Rollen/Rechte) | U35: DSGVO, Mietdokumentation | V35: Light/Pro/Enterprise Abo + Seat-Modell | W35: Live | X35: Yash Bhesaniya | Y35: Welle 3&4 | Z35: 3D-Editor, UrbanMiner, Architect X-Ray | AA35: meine-wohnung.vercel.app
A36: APP-040 | B36: backofficeassistent | C36: GovTech / Pflege | D36: Yash Bhesaniya | E36: 6 | F36: Bürger, Angehörige, Pflegehaushalte | G36: Behördenbriefe und Arztberichte schwer verständlich, Fristen werden verpasst | H36: KI-Analyse von Dokumenten mit Fristenerkennung, Handlungsschritten und PDF-Antwortschreiben | I36: Spezialisierung auf Behörden- und Pflegekontext inkl. Pflegetagebuch-Assistent | J36: Smartlaw, RightNow, FragDenStaat | K36: 9 | L36: 9 | M36: 8 | N36: 7 | O36: 8.25 | P36: 3.3 | Q36: Hoch | R36: 12 | S36: Mittel bis hoch | T36: Next.js 16, TypeScript, Tailwind CSS v4, Supabase, PDF-Parsing/Export | U36: DSGVO, sensible Gesundheitsdaten | V36: Freemium + Pro Abo (10 EUR/Monat) | W36: Live | X36: Yash Bhesaniya | Y36: Welle 6 | Z36: Starker Nutzen bei Fristen- und Formularprozessen | AA36: backofficeassistent.eu
A37: APP-041 | B37: KI-Prüfungstrainer | C37: EdTech | D37: Yash Bhesaniya | E37: 7 | F37: Schüler, Studierende, Weiterbildungslernende | G37: Lernmaterialien werden ineffizient genutzt, fehlende prüfungsnahe Fragen mit Quellenbezug | H37: Upload von PDFs, KI generiert prüfungsähnliche Fragen und bewertet Antworten quellengebunden | I37: Quellengebundene Antworten ohne Halluzinationen, Roh-PDF-Löschung nach Verarbeitung | J37: Quizlet, StudySmarter, Knowunity, Anki | K37: 8 | L37: 7 | M37: 8 | N37: 9 | O37: 8 | P37: 1.6 | Q37: Mittel | R37: 11 | S37: Mittel | T37: Next.js 16, TypeScript, Tailwind CSS v4, Supabase, OpenRouter API, next-intl | U37: DSGVO, Urheberrecht | V37: Freemium + Pro Abo (9,90 EUR/Monat) | W37: Live | X37: Yash Bhesaniya | Y37: Welle 7 | Z37: Exam-Mode und Quellenzitate als Kernnutzen | AA37: ki-prufungstrainer.vercel.app
A38: APP-042 | B38: WG-Planer | C38: Consumer SaaS / Wohnen | D38: Yash Bhesaniya | E38: 8 | F38: WG-Bewohner, Studierende, junge Berufstätige | G38: WG-Organisation über Chat und Excel erzeugt Konflikte bei Geld, Putzplan und Einkäufen | H38: Zentrale WG-App mit Ausgaben-Tracker, Putzplan, Einkaufsliste, Schwarzem Brett und Auszugs-Rechner | I38: All-in-one WG-Operations statt Einzellösungen, inklusive fairem Auszugsabschluss | J38: Splitwise, Flatastic, Bring!, Nipto | K38: 8 | L38: 8 | M38: 9 | N38: 8 | O38: 8.25 | P38: 2.5 | Q38: Mittel | R38: 10 | S38: Mittel bis hoch | T38: Next.js 16, TypeScript, Tailwind CSS v4, Supabase, next-intl | U38: DSGVO | V38: Freemium + Pro Abo (4,99 EUR/Monat) | W38: Live | X38: Yash Bhesaniya | Y38: Welle 8 | Z38: Produktiv erreichbar, | AA38: wgplaner.vercel.app
A39: APP-043 | B39: CardScan | C39: SalesTech / Networking | D39: Yash Bhesaniya | E39: 10 | F39: Vertriebsteams, Berater, Messe-Netzwerker | G39: Papier-Visitenkarten gehen verloren, manuelle Übertragung fehlerhaft | H39: KI-OCR-Scan, digitale Karten, QR-Teilen, CRM-Export | I39: Hohe OCR-Genauigkeit, Offline-Erfassung, DSGVO-Fokus | J39: CamCard, Haystack, ABBYY | K39: 8 | L39: 7 | M39: 8 | N39: 9 | O39: 8 | P39: 1.6 | Q39: Mittel | R39: 14 | S39: Mittel | T39: Next.js 16, TypeScript, Tailwind CSS v4, Supabase, Tesseract OCR | U39: DSGVO | V39: Free, Pro (9 EUR), Team (29 EUR) | W39: Live | X39: Yash Bhesaniya | Y39: Welle 10 | Z39: Produktiv mit klaren Preisstufen und CRM-Export | AA39: cardscan-seven.vercel.app
A40: APP-044 | B40: BuyRight AI | C40: E-Commerce / KI-Shopping-Assistent | D40: Elias Felsing | E40: 10 | F40: Online-Shopper 18–35, Technik-Käufer, Preisbewusste Shopper, Käufer 35–55, Eltern; DACH-Raum | G40: 22 % Retourenquote durch Fehlkäufe; bis zu 42 % gefälschte Amazon-Reviews; kein ganzheitlicher KI-Assistent für Kaufentscheidungen im Markt | H40: Nutzer gibt Produktlink / Bild / Text ein → KI analysiert in <30 Sek. und liefert Score 0–100, Pros/Cons, Warnungen, 3–5 Alternativen + BUY / DON'T BUY-Empfehlung | I40: Einziger Anbieter der KI-Score + BUY/DON'T BUY + Review-Echtheitsprüfung + Preisbewertung + Alternativenvergleich in einem für Laien optimierten Web-Interface kombiniert | J40: Amazon Reviews, FakeSpot (US), ReviewMeta (US), idealo (DE), Google Shopping, Wirecutter (US), ChatGPT / Perplexity | K40: 9 | L40: 8 | M40: 8 | N40: 6 | O40: 25 | P40: 19 | Q40: Mittel | R40: nicht angegeben | S40: Hoch | T40: Next.js 15, TypeScript, Tailwind CSS, shadcn/ui, Supabase EU Frankfurt, OpenAI GPT-4o / Claude Fallback, SerpAPI, Stripe, Resend EU, Plausible EU, Vercel fra1 | U40: DSGVO (Art. 6), EU AI Act 2025, Affiliate-Kennzeichnung §5a UWG, Amazon PA-API / TOS-konforme Nutzung, EU-Hosting | V40: Freemium: Free (3 Checks/Tag) / Pro 9,99 EUR/Monat; Affiliate-Links; Ziel: 1.000 Pro-User = 9.990 EUR MRR | W40: Live | X40: Elias Felsing | Y40: Welle 10 | Z40: V2: Preisverfall-Alerts, Wishlist-Tracking, Browser-Extension. Claim: "Fehlkäufe vermeiden. Besser kaufen." | AA40: https://www.buyrai.eu/
...

Sheet Übersicht
B1: Stand 16.05.2026
B2: Welle | C2: Projektname | D2: App-Name | E2: Typ | F2: Verantwortlicher | G2: Status Wellenabschluss | H2: Status aktuell | I2: Landingpage | J2: Domäne (Strato) | K2: Ablage (OneDrive) | L2: Handbuch | M2: Marketingkonzept | N2: Supabase Projektname | P2: Vercel Projektname | Q2: Git
B3: 1 (KW11) | C3: Marketing Planer | D3: Momentum Marketing | F3: Daniel | G3: Ziel nicht erreicht | I3: https://wamocon.github.io/momentum_marketing_landingpage/ | J3: https://www.momentum-marketing.app/ | Q3: marketing_powerhouse
B4: 1 (KW11) | C4: Architekten Planer | D4: Plan-it | E4: Web-App | F4: Niko | G4: Ziel nicht erreicht | I4: wamocon.github.io/plan-it_landing_ | K4: plan-IT | L4: https://wamocon.github.io/plan-it/ | N4: planIT | P4: plan-it | Q4: plan-it
B5: 1 (KW11) | C5: Backup Planer | D5: urbackup? | F5: Erwin | G5: Ziel nicht erreicht | I5: http://info.backuppilot.app/ | J5: https://backuppilot.app/login | K5: BackupPilot | Q5: urbackup | R5: backup_planner
B6: 1 (KW11) | C6: Ustafix | D6: Ustafix | E6: Web App / PWA | F6: Maanik / Waleri | G6: Ziel erreicht | I6: ustafix-landing-page.vercel.app | J6: ustafix.app | N6: fvhffywxgfsdkenvdvkt | P6: ustafix-app | Q6: ustafix.app
B7: 1 (KW11) | C7: KI Manager | D7: KI Manager LMS | E7: Web App / SaaS | F7: Maanik | G7: Ziel erreicht | I7: ki-manager-lms.vercel.app/lp | J7: ki-manager-lms.vercel.app | K7: 06-01-27 KI-Manager | L7: KI-Manager-LMS_Benutzerhandbuch.docx | N7: acgxydrisfjbilfgatkq | P7: ki-manager-lms | Q7: KI-Manager-LMS
B8: 2 (KW12) | C8: Backup Planer | F8: Erwin | G8: Ziel nicht erreicht
B9: 2 (KW12) | C9: Momentum Marketing | F9: Daniel | G9: Ziel erreicht | P9: wmc-anforderungsportal
B10: 2 (KW12) | C10: Team Radar | D10: TeamRadar | E10: Web-App | F10: Niko | G10: Ziel erreicht | I10: https://curly-couscous-zg4j298.pages.github.io/ | K10: TeamRadar | L10: https://wamocon.github.io/TeamRadar/ | N10: teamradar | P10: klar-app | Q10: TeamRadar
B11: 2 (KW12) | C11: Ustafix V2 | F11: Maanik/Yash | G11: Ziel erreicht | P11: klar-app
B12: 2 (KW12) | C12: Reality Check | F12: Nurzhan | G12: verschoben | P12: Kein Vercel | Q12: realityCheck
B13: 2 (KW12) | C13: LinkedIn & Instagram Automation | D13: SocialHub / Momentum | E13: Web App / SaaS | F13: Maanik | G13: verschoben | I13: momentum_marketing_landingpage (Vercel) | J13: momentum-marketing.app | N13: ftbkqtteavvdqmhbmzoy | Q13: -
B14: 3 (KW13) | C14: Skillmapper | D14: Kompetenzkompass | F14: Daniel | G14: Ziel nicht erreicht | I14: https://wamocon.github.io/kompetenzkompass_lp/ | J14: https://www.kompetenzkompass.app/ | K14: Kompetenzkompass | Q14: skillmapper
B15: 3 (KW13) | C15: Daily Echo | F15: Erwin | G15: Ziel nicht erreicht | I15: https://wamocon.github.io/dailyecho_lp/ | J15: https://www.dailyecho.app/login | K15: daily echo | L15: https://www.dailyecho.app/help | N15: dailyecho | P15: dailyecho | Q15: daily_echo
B16: 3 (KW13) | C16: AWAY | D16: AWAY | E16: Web-App | F16: Niko | G16: Ziel nicht erreicht | I16: https://landingpage.aiaway.de/ | J16: https://www.aiaway.de/auth/login | K16: AWAY_v1 | L16: http://produkthandbuch.aiaway.de/ | N16: teamradar | P16: away | Q16: away
B17: 3 (KW13) | C17: Trace | D17: TRACE | E17: Web-App | F17: Niko | G17: Ziel nicht erreicht | I17: https://redesigned-guide-v3ypon5.pages.github.io/ | K17: TRACE_v1 | L17: https://wamocon.github.io/trace/ | N17: teamradar | P17: trace | Q17: trace
B18: 3 (KW13) | C18: AI SafeGuard | D18: AI SafeGuard | E18: web-extension | F18: Yash | G18: Ziel nicht erreicht | I18: Keine Landingpage notwendig | Q18: ai_safeguard
B19: 3 (KW13) | C19: Meine Wohnung App | D19: Meine Wohnung | F19: Yash | G19: Ziel nicht erreicht | I19: wamocon.github.io/meine_wohnung | J19: https://meine-wohnung.vercel.app/ | K19: meine_wohnung | L19: https://meine-wohnung.vercel.app/handbook | N19: meine wohnung | P19: meine wohnung | Q19: meine_wohnung
B20: 3 (KW13) | C20: Anforderungsmanager | D20: WMC Anforderungsportal | E20: Web App / SaaS | F20: Maanik | G20: Ziel nicht erreicht | I20: Keine Landingpage notwendig | J20: wmc-anforderungsportal.vercel.app | N20: acgxydrisfjbilfgatkq | P20: wmc-anforderungsportal | Q20: WMC-Anforderungsportal
B21: 4 (KW14) | C21: WedBudget | F21: Daniel | G21: Ziel nicht erreicht | I21: https://wamocon.github.io/hochzeitsrechner_lp/ | K21: Hochzeitsrechner(ARBEITSTITEL) | Q21: wedbudget
B22: 4 (KW14) | C22: AWAY V2 | D22: AWAY | E22: Web-App | F22: Niko | G22: Ziel nicht erreicht | I22: https://landingpage.aiaway.de/ | J22: https://www.aiaway.de/auth/login | K22: AWAY_v2 | L22: http://produkthandbuch.aiaway.de/ | N22: teamradar | P22: away | Q22: away
B23: 4 (KW14) | C23: TRACE V2 | D23: TRACE | E23: Web-App | F23: Niko | G23: Ziel nicht erreicht | I23: https://redesigned-guide-v3ypon5.pages.github.io/ | J23: https://trace-livid-kappa.vercel.app/auth/login | K23: TRACE_v2 | L23: https://wamocon.github.io/trace/ | N23: teamradar | P23: trace | Q23: trace
B24: 4 (KW14) | C24: KLAR | D24: KLAR | E24: Web App + Chrome Extension | F24: Maanik | G24: Ziel nicht erreicht | I24: klar-app.vercel.app/lp | J24: klar-app.vercel.app | K24: 06-01-23 KLAR | L24: KLAR_Benutzerhandbuch_DE.docx | N24: jjarhxxfcagapeaahntw | P24: klar-app | Q24: KLAR
B25: 4 (KW14) | C25: Meine Wohnung App | D25: Meine Wohnung | E25: Web-App | F25: Yash | G25: Ziel nicht erreicht | I25: wamocon.github.io/meine_wohnung | K25: meine_wohnung | L25: https://meine-wohnung.vercel.app/handbook | N25: meine wohnung | P25: meine wohnung
B26: 4 (KW14) | C26: Energieberater/Saniatlas | F26: Erwin | G26: Ziel nicht erreicht | Q26: energy
B27: 5 (KW15) | C27: KLAR V2 | D27: KLAR V2 | E27: Web App + Chrome Extension | F27: Maanik | G27: bedingt erreicht | I27: klar-app.vercel.app/lp | J27: klar-app.vercel.app | K27: 06-01-23 KLAR | L27: KLAR_Benutzerhandbuch_DE.docx | N27: jjarhxxfcagapeaahntw | P27: klar-app
B28: 5 (KW15) | C28: CarMan | F28: Daniel | G28: bedingt erreicht | I28: wamocon.github.io/carman_lp/ | K28: 01_Freigabe erteilt_CarMan | Q28: carman
B29: 5 (KW15) | C29: Universal Inventory Manager | F29: Yash | G29: Ziel nicht erreicht | I29: Keine Landingpage notwendig | Q29: Universal_Inventory_Manager
B30: 5 (KW15) | C30: Team Radar V2 | D30: TeamRadar | E30: Web-App | F30: Niko | G30: Ziel nicht erreicht | I30: https://curly-couscous-zg4j298.pages.github.io/ | J30: https://teamradar.vercel.app/auth/login | K30: TeamRadar | L30: https://wamocon.github.io/TeamRadar/ | N30: teamradar | P30: TeamRadar | Q30: TeamRadar
B31: 5 (KW15) | C31: BFSG Audit Tool | F31: Erwin | G31: Ziel nicht erreicht
B32: 6 (KW16) | C32: Vertragsmanager | D32: VerWa (Vertragswächterin) | F32: Daniel | G32: Ziel nicht erreicht | I32: Wamocon.github.io/vertragsmanage | J32: http://verwa.eu/ | K32: 02_Freigabe erteilt_02_Vertragsmanager | Q32: vertragsmanager
B33: 6 (KW16) | C33: ladeKompass | D33: LadeKompass | E33: Web-App | F33: Niko | G33: Ziel erreicht | I33: https://landingpage.ladekompass.com/ | J33: https://www.ladekompass.com/de/ | K33: 01_Freigabe erteilt_LadesäulenChaos | L33: https://produkthandbuch.ladekompass.com/ | N33: ladeKompass | P33: ladekompass | Q33: ladeKompass
B34: 6 (KW16) | C34: Max | D34: MAX AI Stack | E34: Lokale KI-Plattform | F34: Maanik | G34: bedingt erreicht | J34: Lokal / LAN | K34: 06-01-28 Lokal KI | L34: BENUTZERHANDBUCH.docx | N34: Kein Supabase | P34: Kein Vercel
B35: 6 (KW16) | C35: backofficeassistent | D35: backofficeassistent | E35: Web-App | F35: Yash | G35: Ziel erreicht | I35: wamocon.github.io/backofficeassiste | J35: https://www.backofficeassistent.eu/ | K35: 03_Freigabe erteilt_Bürokratie-Copilot | L35: https://www.backofficeassistent.eu/de/handbook | N35: backofficeassistent | P35: backofficeassistent | Q35: backofficeassistent
B36: 7 (KW17) | C36: Bedarfspilot | F36: Daniel | G36: Ziel nicht erreicht | I36: Wamocon.github.io/bedarfspilot_lp/ | J36: http://bedarfspilot.de/ | K36: 01_Freigabe erteilt_BedarfsPilot | Q36: bedarfspilot
B37: 7 (KW17) | C37: KI-Prüfungstrainer | D37: KI-Prüfungstrainer | F37: Yash | G37: Ziel nicht erreicht | I37: Wamocon.github.io/KI-Prufungstrain | J37: https://ki-prufungstrainer.vercel.app/de | K37: 05_Freigabe erteilt_KI-Prüfungstrainer | L37: https://ki-prufungstrainer.vercel.app/de/manual | N37: KITrainer | P37: ki-prufungstrainer | Q37: ki-prufungstrainer
B38: 7 (KW17) | C38: ARIA | D38: ARIA | E38: Web App / Medical AI | F38: Maanik | G38: Ziel nicht erreicht | J38: aria-ten-kohl.vercel.app | K38: 04_Freigabe erteilt_ARIA | N38: jjarhxxfcagapeaahntw (Schema: aria) | P38: aria-ten-kohl | Q38: ARIA
B39: 7 (KW17) | C39: LocalForge | F39: Leon | G39: Ziel nicht erreicht | I39: Wamocon.github.io/LocalForge_lp/ | K39: 06_Freigabe erteilt_LocalForge | Q39: localforge
B40: 8 (KW18) | C40: LocalForge | F40: Leon | G40: Ziel nicht erreicht
...

Sheet Status
B2: Täglicher Status zu den Apps
A3: 46106
B4: ID | C4: App-Name | D4: Verantwortlicher | E4: Welle | F4: Status
B5: APP-013 | C5: WedBudget | D5: Daniel | E5: 3
B6: APP-001 | C6: Rent Navigator | D6: Waleri | E6: 3
B7: APP-012 | C7: DailyEcho | D7: Erwin | E7: 3
B8: APP-004 | C8: Skillmapping | D8: Daniel | E8: 3
B9: APP-022 | C9: Zeiterfassung | D9: Niko | E9: 3
B10: APP-023 | C10: Urlaubsplaner | D10: Niko | E10: 3
B11: APP-024 | C11: Reality Check | D11: Nurzhan | E11: 3
B12: APP-025 | C12: Linkedin&Instagram Automation | D12: Maanik | E12: 3
B13: APP-026 | C13: KLAR (Knowledge Legitimacy Audit & Review) | D13: Maanik | E13: 3
B14: APP-027 | C14: WAMOCON CRM System | D14: Yash | E14: 3
A21: 46106
B22: ID | C22: App-Name | D22: Verantwortlicher | E22: Welle | F22: Status
B23: APP-013 | C23: WedBudget | D23: Daniel | E23: 3
B24: APP-001 | C24: Rent Navigator | D24: Waleri | E24: 3
B25: APP-012 | C25: DailyEcho | D25: Erwin | E25: 3
B26: APP-004 | C26: Skillmapping | D26: Daniel | E26: 3
B27: APP-022 | C27: Zeiterfassung | D27: Niko | E27: 3
B28: APP-023 | C28: Urlaubsplaner | D28: Niko | E28: 3
B29: APP-024 | C29: Reality Check | D29: Nurzhan | E29: 3
B30: APP-025 | C30: Linkedin&Instagram Automation | D30: Maanik | E30: 3
B31: APP-026 | C31: KLAR (Knowledge Legitimacy Audit & Review) | D31: Maanik | E31: 3
B32: APP-027 | C32: WAMOCON CRM System | D32: Yash | E32: 3
A38: 46107
B39: ID | C39: App-Name | D39: Verantwortlicher | E39: Welle | F39: Status
B40: APP-013 | C40: WedBudget | D40: Daniel | E40: 3
B41: APP-001 | C41: Rent Navigator | D41: Waleri | E41: 3
B42: APP-012 | C42: DailyEcho | D42: Erwin | E42: 3
B43: APP-004 | C43: Skillmapping | D43: Daniel | E43: 3
B44: APP-022 | C44: Zeiterfassung | D44: Niko | E44: 3
B45: APP-023 | C45: Urlaubsplaner | D45: Niko | E45: 3
B46: APP-024 | C46: Reality Check | D46: Nurzhan | E46: 3
B47: APP-025 | C47: Linkedin&Instagram Automation | D47: Maanik | E47: 3
B48: APP-026 | C48: KLAR (Knowledge Legitimacy Audit & Review) | D48: Maanik | E48: 3
B49: APP-027 | C49: WAMOCON CRM System | D49: Yash | E49: 3
A55: 46108
B56: ID | C56: App-Name | D56: Verantwortlicher | E56: Welle | F56: Status
B57: APP-013 | C57: WedBudget | D57: Daniel | E57: 3
...

Sheet Trendanalyse TOP 50
A1: Rang | B1: Branche | C1: Thema | D1: Problem-Name | E1: Kurzbeschreibung | F1: DE-Relevanz (1-4) | G1: Int. Auswirkung | H1: Bestehende Lösungen | I1: Lösungslücke | J1: Marktpotenzial (1-10) | K1: Dringlichkeit (1-10) | L1: Machbarkeit (1-10) | M1: Wettbewerb (1-10) | N1: Gesamtscore | O1: Opportunity Score | P1: Opportunity Rang | Q1: Quelle/Referenz | R1: Bemerkungen
A2: 27 | B2: Verwaltung | C2: Behördendigitalisierung | D2: E-Government Rückstand | E2: Deutschland im EU-Vergleich hinten, föderale Strukturen bremsen | F2: 4 | G2: Deutschland-spezifisch | H2: Einzelprojekte | I2: Standardisierte Kommune-Software fehlt | J2: 9 | K2: 10 | L2: 5 | M2: 4 | N2: =AVERAGE(J2:M2) -> 7 | O2: =(J2+K2+L2)*(10-M2)/30 -> 4.8 | P2: =RANK(O2,$O$2:$O$51,0) -> 1 | Q2: bidt 2025 | R2: OZG-Umsetzung
A3: 3 | B3: Gesundheit | C3: Home Care | D3: Häusliche Pflege Technologie | E3: Patienten kämpfen mit Bedienung von Heimgeräten, Fehler unentdeckt | F3: 3 | G3: Industrieländer | H3: Wenige spezialisierte Apps | I3: Integrierte Überwachungs- und Support-Plattform fehlt | J3: 8 | K3: 8 | L3: 7 | M3: 4 | N3: =AVERAGE(J3:M3) -> 6.75 | O3: =(J3+K3+L3)*(10-M3)/30 -> 4.6 | P3: =RANK(O3,$O$2:$O$51,0) -> 2 | Q3: Healthcare IT News 2025 | R3: Demografischer Wandel
A4: 28 | B4: Verwaltung | C4: Bürgerservices | D4: Digitale Bürgeranträge | E4: Bürger müssen persönlich aufs Amt für viele Anträge | F4: 4 | G4: Deutschland | H4: Fragmentierte Portale | I4: Einheitliches Bürgerportal mit KI-Assistenz fehlt | J4: 8 | K4: 9 | L4: 6 | M4: 4 | N4: =AVERAGE(J4:M4) -> 6.75 | O4: =(J4+K4+L4)*(10-M4)/30 -> 4.6 | P4: =RANK(O4,$O$2:$O$51,0) -> 2 | Q4: Computer Weekly 2025 | R4: eID nutzen
A5: 29 | B5: Bauwesen | C5: IoT Baustelle | D5: Baustellendigitalisierung | E5: 62% sehen IoT-Potenzial, nur 10% haben Fähigkeiten | F5: 4 | G5: DACH | H5: BIM-Tools (komplex) | I5: Einfache IoT-Plattform für Baustellen fehlt | J5: 8 | K5: 8 | L5: 6 | M5: 4 | N5: =AVERAGE(J5:M5) -> 6.5 | O5: =(J5+K5+L5)*(10-M5)/30 -> 4.4 | P5: =RANK(O5,$O$2:$O$51,0) -> 4 | Q5: PwC Baustudie 2025 | R5: Plug & Play IoT
A6: 1 | B6: Gesundheit | C6: Diagnostik | D6: Diagnostische Fehler | E6: 795.000 schwere Schäden jährlich durch Fehldiagnosen, 371.000 Todesfälle | F6: 3 | G6: Weltweit kritisch | H6: Vereinzelte KI-Tools | I6: Integrierte KI-Diagnostik für Hausärzte fehlt | J6: 9 | K6: 10 | L6: 7 | M6: 5 | N6: =AVERAGE(J6:M6) -> 7.75 | O6: =(J6+K6+L6)*(10-M6)/30 -> 4.3333333 | P6: =RANK(O6,$O$2:$O$51,0) -> 5 | Q6: BMJ Quality & Safety 2023 | R6: Regulatorische Hürden (MDR)
A7: 41 | B7: KI/Tech | C7: Agentic AI | D7: KI-Agenten Governance | E7: 40% Agentic-AI-Projekte scheitern bis 2027 | F7: 3 | G7: Global | H7: Frühe Tools | I7: KI-Agenten-Governance-Framework fehlt | J7: 8 | K7: 8 | L7: 5 | M7: 4 | N7: =AVERAGE(J7:M7) -> 6.25 | O7: =(J7+K7+L7)*(10-M7)/30 -> 4.2 | P7: =RANK(O7,$O$2:$O$51,0) -> 6 | Q7: Gartner 2025 | R7: Neues Feld
A8: 7 | B8: Immobilien | C8: Nachhaltigkeit | D8: ESG-Compliance Gebäude | E8: 88% PropTech-Investments in Energieeffizienz, Lösungslücke bei Bestand | F8: 4 | G8: EU-weit (CSRD) | H8: Vereinzelte Tools | I8: Ganzheitliche ESG-Management-Plattform für Bestand fehlt | J8: 9 | K8: 9 | L8: 7 | M8: 5 | N8: =AVERAGE(J8:M8) -> 7.5 | O8: =(J8+K8+L8)*(10-M8)/30 -> 4.1666667 | P8: =RANK(O8,$O$2:$O$51,0) -> 7 | Q8: PropTech Global Trends 2024 | R8: CSRD-Pflicht ab 2025
A9: 24 | B9: Energie | C9: Energiemanagement | D9: Energiekosten KMU | E9: Energiepreise belasten KMU, fehlende Transparenz | F9: 4 | G9: EU | H9: Smart Meter (B2C) | I9: Energiemanagement-Plattform für KMU fehlt | J9: 8 | K9: 9 | L9: 7 | M9: 5 | N9: =AVERAGE(J9:M9) -> 7.25 | O9: =(J9+K9+L9)*(10-M9)/30 -> 4 | P9: =RANK(O9,$O$2:$O$51,0) -> 8 | Q9: WEF 2025 | R9: CSRD-Reporting
A10: 39 | B10: Landwirtschaft | C10: Precision Farming | D10: Digitalisierung Höfe | E10: Kleine Höfe haben keinen Zugang zu Smart Farming | F10: 3 | G10: DACH | H10: Große Anbieter (John Deere) | I10: Bezahlbare IoT-Lösung für Kleinbauern fehlt | J10: 7 | K10: 7 | L10: 6 | M10: 4 | N10: =AVERAGE(J10:M10) -> 6 | O10: =(J10+K10+L10)*(10-M10)/30 -> 4 | P10: =RANK(O10,$O$2:$O$51,0) -> 8 | Q10: AgTech 2025 | R10: Subventionen
A11: 40 | B11: Landwirtschaft | C11: Lebensmittelverschwendung | D11: Food Waste | E11: 30-40% Lebensmittel werden verschwendet | F11: 4 | G11: Global | H11: Too Good To Go (B2C) | I11: B2B Food-Waste-Plattform für Produzenten fehlt | J11: 8 | K11: 9 | L11: 7 | M11: 5 | N11: =AVERAGE(J11:M11) -> 7.25 | O11: =(J11+K11+L11)*(10-M11)/30 -> 4 | P11: =RANK(O11,$O$2:$O$51,0) -> 8 | Q11: Raconteur 2025 | R11: ESG-Relevanz
A12: 5 | B12: Gesundheit | C12: Datensicherheit | D12: Healthcare Cyberangriffe | E12: Größte Datenpanne: 100 Mio. Patienten betroffen (Change Healthcare) | F12: 4 | G12: Global | H12: Standard IT-Security | I12: Healthcare-spezifische Sicherheitsplattform fehlt | J12: 8 | K12: 9 | L12: 6 | M12: 5 | N12: =AVERAGE(J12:M12) -> 7 | O12: =(J12+K12+L12)*(10-M12)/30 -> 3.8333333 | P12: =RANK(O12,$O$2:$O$51,0) -> 11 | Q12: HIPAA Journal 2025 | R12: Kritische Infrastruktur
A13: 16 | B13: Logistik | C13: Systemintegration | D13: Daten-Silos | E13: Fragmentierte Legacy-Systeme, fehlende gemeinsame Datensprache | F13: 3 | G13: Global | H13: SAP, Oracle (komplex) | I13: Middleware für KMU-Logistik fehlt | J13: 8 | K13: 8 | L13: 7 | M13: 5 | N13: =AVERAGE(J13:M13) -> 7 | O13: =(J13+K13+L13)*(10-M13)/30 -> 3.8333333 | P13: =RANK(O13,$O$2:$O$51,0) -> 11 | Q13: Logistics Viewpoints 2025 | R13: Interoperabilität
... A51: 36 | B51: HR/Personal | C51: Zeiterfassung | D51: Arbeitszeitgesetz | E51: EuGH-Urteil: Zeiterfassung Pflicht, viele KMU nicht compliant | F51: 4 | G51: EU | H51: Viele Tools | I51: Einfache, rechtssichere Lösung für Kleinst-KMU fehlt | J51: 6 | K51: 8 | L51: 9 | M51: 8 | N51: =AVERAGE(J51:M51) -> 7.75 | O51: =(J51+K51+L51)*(10-M51)/30 -> 1.5333333 | P51: =RANK(O51,$O$2:$O$51,0) -> 50 | Q51: DIHK 2025 | R51: Hoher Wettbewerb

Sheet Domänen
D5: Produkt | E5: Domäne
D6: LFA - Lernzentrum für Auszubildende | E6: meinlfa.ai
E7: lfahub.ai
E8: lernzentrum.ai
E9: azubipro.ai
D10: SIT - Systemintegration (Ausbuldungberuf) | E10: sit-learn.ai
E11: sit-learn.com
D12: DaPro - Daten- & Prozessanalyse (Ausbildungsberuf) | E12: dapro-learn.ai
E13: dapro-learn.com
D14: DiVer - Digitale Vernetzung | E14: diver-learn.ai
E15: diver-learn.com
